Workbook

Sheet Summary
A1: TMS Unbilled Broker Loads
A3: Report | B3: =Parameters!B2 -> Unbilled Broker Loads
A4: Company | B4: =Parameters!B3 -> Lakeshore Freight Logistics
A5: Accrual period | B5: =Parameters!B5 -> OCT-26
A6: As-of date | B6: =Parameters!B7 -> 46326
A7: Generated (CT) | B7: =Parameters!B8 -> 46325.578
A8: Generated by | B8: =Parameters!B10 -> mkeane
A10: Unbilled loads | B10: =COUNTA('Load Detail'!A2:A103) -> 102
A11: Linehaul | B11: =SUM('Load Detail'!I2:I103) -> 154190
A12: Fuel surcharge | B12: =SUM('Load Detail'!J2:J103) -> 29480
A13: Accessorials | B13: =SUM('Load Detail'!K2:K103) -> 2750
A14: Total unbilled cost | B14: =SUM(B11:B13) -> 186420
A16: GL debit | B16: =Parameters!B18 -> 5120-000 Purchased Transportation, Brokers
A17: GL credit | B17: =Parameters!B19 -> 2150-000 Accrued Freight
A18: Reversal | B18: =Parameters!B20 -> Auto-reverses on day 1 of the next period (NOV-26)
A20: Check: Load Detail total | B20: =B14-'Load Detail'!M105 -> 0
A21: Check: By Broker total | B21: =B14-'By Broker'!G9 -> 0
A22: Check: Aging total | B22: =B14-Aging!E6 -> 0

Sheet Load Detail
A1: Load # | B1: Broker | C1: Origin | D1: Destination | E1: Equipment | F1: Pickup date | G1: Delivery date | H1: Miles | I1: Linehaul | J1: Fuel surcharge | K1: Accessorials | L1: Accessorial detail | M1: Total cost | N1: Days since delivery | O1: Aging bucket | P1: Freight bill status | Q1: Freight pay note
A2: LFL-1046547 | B2: Ironbridge Logistics Brokerage LLC | C2: Gary, IN | D2: Memphis, TN | E2: Power only | F2: 46296 | G2: 46297 | H2: 528 | I2: 1110 | J2: 238 | M2: =SUM(I2:K2) -> 1348 | N2: =Parameters!$B$7-G2 -> 29 | O2: =IF(N2<=7,"0-7 days",IF(N2<=14,"8-14 days",IF(N2<=30,"15-30 days","Over 30 days"))) -> 15-30 days | P2: Monthly statement pending
A3: LFL-1046604 | B3: Ironbridge Logistics Brokerage LLC | C3: Gary, IN | D3: Dallas, TX | E3: Dry van 53 ft | F3: 46298 | G3: 46300 | H3: 932 | I3: 2095 | J3: 419 | M3: =SUM(I3:K3) -> 2514 | N3: =Parameters!$B$7-G3 -> 26 | O3: =IF(N3<=7,"0-7 days",IF(N3<=14,"8-14 days",IF(N3<=30,"15-30 days","Over 30 days"))) -> 15-30 days | P3: Monthly statement pending
A4: LFL-1046776 | B4: Ironbridge Logistics Brokerage LLC | C4: Memphis, TN | D4: Gary, IN | E4: Power only | F4: 46301 | G4: 46302 | H4: 528 | I4: 1135 | J4: 238 | M4: =SUM(I4:K4) -> 1373 | N4: =Parameters!$B$7-G4 -> 24 | O4: =IF(N4<=7,"0-7 days",IF(N4<=14,"8-14 days",IF(N4<=30,"15-30 days","Over 30 days"))) -> 15-30 days | P4: Monthly statement pending
A5: LFL-1046791 | B5: Ironbridge Logistics Brokerage LLC | C5: Gary, IN | D5: Houston, TX | E5: Dry van 53 ft | F5: 46302 | G5: 46304 | H5: 1061 | I5: 2130 | J5: 477 | K5: 100 | L5: Detention 2 hr | M5: =SUM(I5:K5) -> 2707 | N5: =Parameters!$B$7-G5 -> 22 | O5: =IF(N5<=7,"0-7 days",IF(N5<=14,"8-14 days",IF(N5<=30,"15-30 days","Over 30 days"))) -> 15-30 days | P5: Monthly statement pending
A6: LFL-1047051 | B6: Ironbridge Logistics Brokerage LLC | C6: Gary, IN | D6: Memphis, TN | E6: Power only | F6: 46307 | G6: 46308 | H6: 528 | I6: 1130 | J6: 238 | M6: =SUM(I6:K6) -> 1368 | N6: =Parameters!$B$7-G6 -> 18 | O6: =IF(N6<=7,"0-7 days",IF(N6<=14,"8-14 days",IF(N6<=30,"15-30 days","Over 30 days"))) -> 15-30 days | P6: Monthly statement pending
A7: LFL-1047147 | B7: Ironbridge Logistics Brokerage LLC | C7: Memphis, TN | D7: Columbus, OH | E7: Dry van 53 ft | F7: 46309 | G7: 46310 | H7: 585 | I7: 1435 | J7: 263 | M7: =SUM(I7:K7) -> 1698 | N7: =Parameters!$B$7-G7 -> 16 | O7: =IF(N7<=7,"0-7 days",IF(N7<=14,"8-14 days",IF(N7<=30,"15-30 days","Over 30 days"))) -> 15-30 days | P7: Monthly statement pending
A8: LFL-1047143 | B8: Ironbridge Logistics Brokerage LLC | C8: Gary, IN | D8: Dallas, TX | E8: Dry van 53 ft | F8: 46309 | G8: 46311 | H8: 932 | I8: 2025 | J8: 419 | M8: =SUM(I8:K8) -> 2444 | N8: =Parameters!$B$7-G8 -> 15 | O8: =IF(N8<=7,"0-7 days",IF(N8<=14,"8-14 days",IF(N8<=30,"15-30 days","Over 30 days"))) -> 15-30 days | P8: Monthly statement pending
A9: LFL-1047257 | B9: Ironbridge Logistics Brokerage LLC | C9: Gary, IN | D9: Atlanta, GA | E9: Dry van 53 ft | F9: 46312 | G9: 46314 | H9: 688 | I9: 1650 | J9: 310 | M9: =SUM(I9:K9) -> 1960 | N9: =Parameters!$B$7-G9 -> 12 | O9: =IF(N9<=7,"0-7 days",IF(N9<=14,"8-14 days",IF(N9<=30,"15-30 days","Over 30 days"))) -> 8-14 days | P9: Monthly statement pending
A10: LFL-1047391 | B10: Ironbridge Logistics Brokerage LLC | C10: Memphis, TN | D10: Gary, IN | E10: Power only | F10: 46315 | G10: 46316 | H10: 528 | I10: 1090 | J10: 238 | M10: =SUM(I10:K10) -> 1328 | N10: =Parameters!$B$7-G10 -> 10 | O10: =IF(N10<=7,"0-7 days",IF(N10<=14,"8-14 days",IF(N10<=30,"15-30 days","Over 30 days"))) -> 8-14 days | P10: Monthly statement pending
A11: LFL-1047455 | B11: Ironbridge Logistics Brokerage LLC | C11: Gary, IN | D11: Dallas, TX | E11: Dry van 53 ft | F11: 46316 | G11: 46318 | H11: 932 | I11: 2060 | J11: 419 | K11: 240 | L11: Lumper | M11: =SUM(I11:K11) -> 2719 | N11: =Parameters!$B$7-G11 -> 8 | O11: =IF(N11<=7,"0-7 days",IF(N11<=14,"8-14 days",IF(N11<=30,"15-30 days","Over 30 days"))) -> 8-14 days | P11: Monthly statement pending
A12: LFL-1047603 | B12: Ironbridge Logistics Brokerage LLC | C12: Gary, IN | D12: Houston, TX | E12: Dry van 53 ft | F12: 46319 | G12: 46321 | H12: 1061 | I12: 2190 | J12: 477 | M12: =SUM(I12:K12) -> 2667 | N12: =Parameters!$B$7-G12 -> 5 | O12: =IF(N12<=7,"0-7 days",IF(N12<=14,"8-14 days",IF(N12<=30,"15-30 days","Over 30 days"))) -> 0-7 days | P12: Monthly statement pending
A13: LFL-1047705 | B13: Ironbridge Logistics Brokerage LLC | C13: Gary, IN | D13: Memphis, TN | E13: Power only | F13: 46322 | G13: 46323 | H13: 528 | I13: 1145 | J13: 238 | M13: =SUM(I13:K13) -> 1383 | N13: =Parameters!$B$7-G13 -> 3 | O13: =IF(N13<=7,"0-7 days",IF(N13<=14,"8-14 days",IF(N13<=30,"15-30 days","Over 30 days"))) -> 0-7 days | P13: Monthly statement pending
A14: LFL-1047763 | B14: Ironbridge Logistics Brokerage LLC | C14: Memphis, TN | D14: Gary, IN | E14: Power only | F14: 46323 | G14: 46324 | H14: 528 | I14: 1080 | J14: 238 | M14: =SUM(I14:K14) -> 1318 | N14: =Parameters!$B$7-G14 -> 2 | O14: =IF(N14<=7,"0-7 days",IF(N14<=14,"8-14 days",IF(N14<=30,"15-30 days","Over 30 days"))) -> 0-7 days | P14: Monthly statement pending
A15: LFL-1046117 | B15: Copperline Freight Brokerage Inc. | C15: Gary, IN | D15: Harrisburg, PA | E15: Dry van 53 ft | F15: 46287 | G15: 46289 | H15: 668 | I15: 1605 | J15: 307 | M15: =SUM(I15:K15) -> 1912 | N15: =Parameters!$B$7-G15 -> 37 | O15: =IF(N15<=7,"0-7 days",IF(N15<=14,"8-14 days",IF(N15<=30,"15-30 days","Over 30 days"))) -> Over 30 days | P15: Received, on hold | Q15: Broker invoice adds a $250.00 layover that is not on the rate confirmation. Accrued at rate confirmation.
A16: LFL-1047063 | B16: Copperline Freight Brokerage Inc. | C16: Joliet, IL | D16: Allentown, PA | E16: Dry van 53 ft | F16: 46308 | G16: 46310 | H16: 772 | I16: 1750 | J16: 355 | M16: =SUM(I16:K16) -> 2105 | N16: =Parameters!$B$7-G16 -> 16 | O16: =IF(N16<=7,"0-7 days",IF(N16<=14,"8-14 days",IF(N16<=30,"15-30 days","Over 30 days"))) -> 15-30 days | P16: Not received
A17: LFL-1047150 | B17: Copperline Freight Brokerage Inc. | C17: Gary, IN | D17: Pittsburgh, PA | E17: Dry van 53 ft | F17: 46310 | G17: 46311 | H17: 437 | I17: 1260 | J17: 201 | K17: 100 | L17: Detention 2 hr | M17: =SUM(I17:K17) -> 1561 | N17: =Parameters!$B$7-G17 -> 15 | O17: =IF(N17<=7,"0-7 days",IF(N17<=14,"8-14 days",IF(N17<=30,"15-30 days","Over 30 days"))) -> 15-30 days | P17: Not received
A18: LFL-1047198 | B18: Copperline Freight Brokerage Inc. | C18: Gary, IN | D18: Cleveland, OH | E18: Dry van 53 ft | F18: 46311 | G18: 46314 | H18: 318 | I18: 915 | J18: 146 | M18: =SUM(I18:K18) -> 1061 | N18: =Parameters!$B$7-G18 -> 12 | O18: =IF(N18<=7,"0-7 days",IF(N18<=14,"8-14 days",IF(N18<=30,"15-30 days","Over 30 days"))) -> 8-14 days | P18: Not received
A19: LFL-1047287 | B19: Copperline Freight Brokerage Inc. | C19: Bolingbrook, IL | D19: Charlotte, NC | E19: Dry van 53 ft | F19: 46312 | G19: 46314 | H19: 783 | I19: 1745 | J19: 360 | M19: =SUM(I19:K19) -> 2105 | N19: =Parameters!$B$7-G19 -> 12 | O19: =IF(N19<=7,"0-7 days",IF(N19<=14,"8-14 days",IF(N19<=30,"15-30 days","Over 30 days"))) -> 8-14 days | P19: Not received
A20: LFL-1047358 | B20: Copperline Freight Brokerage Inc. | C20: Elk Grove Village, IL | D20: Buffalo, NY | E20: Dry van 53 ft | F20: 46314 | G20: 46315 | H20: 563 | I20: 1355 | J20: 259 | M20: =SUM(I20:K20) -> 1614 | N20: =Parameters!$B$7-G20 -> 11 | O20: =IF(N20<=7,"0-7 days",IF(N20<=14,"8-14 days",IF(N20<=30,"15-30 days","Over 30 days"))) -> 8-14 days | P20: Not received
A21: LFL-1047365 | B21: Copperline Freight Brokerage Inc. | C21: Gary, IN | D21: Columbus, OH | E21: Dry van 53 ft | F21: 46314 | G21: 46315 | H21: 331 | I21: 920 | J21: 152 | M21: =SUM(I21:K21) -> 1072 | N21: =Parameters!$B$7-G21 -> 11 | O21: =IF(N21<=7,"0-7 days",IF(N21<=14,"8-14 days",IF(N21<=30,"15-30 days","Over 30 days"))) -> 8-14 days | P21: Not received
A22: LFL-1047356 | B22: Copperline Freight Brokerage Inc. | C22: Gary, IN | D22: Edison, NJ | E22: Dry van 53 ft | F22: 46314 | G22: 46316 | H22: 791 | I22: 1830 | J22: 364 | K22: 275 | L22: Lumper | M22: =SUM(I22:K22) -> 2469 | N22: =Parameters!$B$7-G22 -> 10 | O22: =IF(N22<=7,"0-7 days",IF(N22<=14,"8-14 days",IF(N22<=30,"15-30 days","Over 30 days"))) -> 8-14 days | P22: Not received
A23: LFL-1047381 | B23: Copperline Freight Brokerage Inc. | C23: Gary, IN | D23: Baltimore, MD | E23: Dry van 53 ft | F23: 46315 | G23: 46317 | H23: 683 | I23: 1665 | J23: 314 | M23: =SUM(I23:K23) -> 1979 | N23: =Parameters!$B$7-G23 -> 9 | O23: =IF(N23<=7,"0-7 days",IF(N23<=14,"8-14 days",IF(N23<=30,"15-30 days","Over 30 days"))) -> 8-14 days | P23: Not received
A24: LFL-1047461 | B24: Copperline Freight Brokerage Inc. | C24: Joliet, IL | D24: Columbus, OH | E24: Dry van 53 ft | F24: 46316 | G24: 46317 | H24: 372 | I24: 1035 | J24: 171 | M24: =SUM(I24:K24) -> 1206 | N24: =Parameters!$B$7-G24 -> 9 | O24: =IF(N24<=7,"0-7 days",IF(N24<=14,"8-14 days",IF(N24<=30,"15-30 days","Over 30 days"))) -> 8-14 days | P24: Not received
A25: LFL-1047496 | B25: Copperline Freight Brokerage Inc. | C25: Gary, IN | D25: Cleveland, OH | E25: Dry van 53 ft | F25: 46317 | G25: 46318 | H25: 318 | I25: 910 | J25: 146 | M25: =SUM(I25:K25) -> 1056 | N25: =Parameters!$B$7-G25 -> 8 | O25: =IF(N25<=7,"0-7 days",IF(N25<=14,"8-14 days",IF(N25<=30,"15-30 days","Over 30 days"))) -> 8-14 days | P25: Not received
A26: LFL-1047571 | B26: Copperline Freight Brokerage Inc. | C26: Gary, IN | D26: Harrisburg, PA | E26: Dry van 53 ft | F26: 46319 | G26: 46321 | H26: 668 | I26: 1595 | J26: 307 | K26: 125 | L26: Stop-off (1) | M26: =SUM(I26:K26) -> 2027 | N26: =Parameters!$B$7-G26 -> 5 | O26: =IF(N26<=7,"0-7 days",IF(N26<=14,"8-14 days",IF(N26<=30,"15-30 days","Over 30 days"))) -> 0-7 days | P26: Not received
A27: LFL-1047596 | B27: Copperline Freight Brokerage Inc. | C27: Joliet, IL | D27: Allentown, PA | E27: Dry van 53 ft | F27: 46319 | G27: 46321 | H27: 772 | I27: 1740 | J27: 355 | M27: =SUM(I27:K27) -> 2095 | N27: =Parameters!$B$7-G27 -> 5 | O27: =IF(N27<=7,"0-7 days",IF(N27<=14,"8-14 days",IF(N27<=30,"15-30 days","Over 30 days"))) -> 0-7 days | P27: Not received
A28: LFL-1047546 | B28: Copperline Freight Brokerage Inc. | C28: Bolingbrook, IL | D28: Charlotte, NC | E28: Dry van 53 ft | F28: 46318 | G28: 46322 | H28: 783 | I28: 1800 | J28: 360 | M28: =SUM(I28:K28) -> 2160 | N28: =Parameters!$B$7-G28 -> 4 | O28: =IF(N28<=7,"0-7 days",IF(N28<=14,"8-14 days",IF(N28<=30,"15-30 days","Over 30 days"))) -> 0-7 days | P28: Not received
A29: LFL-1047686 | B29: Copperline Freight Brokerage Inc. | C29: Gary, IN | D29: Pittsburgh, PA | E29: Dry van 53 ft | F29: 46321 | G29: 46322 | H29: 437 | I29: 1205 | J29: 201 | M29: =SUM(I29:K29) -> 1406 | N29: =Parameters!$B$7-G29 -> 4 | O29: =IF(N29<=7,"0-7 days",IF(N29<=14,"8-14 days",IF(N29<=30,"15-30 days","Over 30 days"))) -> 0-7 days | P29: Not received
A30: LFL-1047670 | B30: Copperline Freight Brokerage Inc. | C30: Gary, IN | D30: Edison, NJ | E30: Dry van 53 ft | F30: 46321 | G30: 46323 | H30: 791 | I30: 1755 | J30: 364 | M30: =SUM(I30:K30) -> 2119 | N30: =Parameters!$B$7-G30 -> 3 | O30: =IF(N30<=7,"0-7 days",IF(N30<=14,"8-14 days",IF(N30<=30,"15-30 days","Over 30 days"))) -> 0-7 days | P30: Not received
A31: LFL-1047708 | B31: Copperline Freight Brokerage Inc. | C31: Elk Grove Village, IL | D31: Buffalo, NY | E31: Dry van 53 ft | F31: 46322 | G31: 46323 | H31: 563 | I31: 1385 | J31: 259 | M31: =SUM(I31:K31) -> 1644 | N31: =Parameters!$B$7-G31 -> 3 | O31: =IF(N31<=7,"0-7 days",IF(N31<=14,"8-14 days",IF(N31<=30,"15-30 days","Over 30 days"))) -> 0-7 days | P31: Not received
A32: LFL-1047702 | B32: Copperline Freight Brokerage Inc. | C32: Gary, IN | D32: Baltimore, MD | E32: Dry van 53 ft | F32: 46322 | G32: 46324 | H32: 683 | I32: 1710 | J32: 314 | K32: 75 | L32: Detention 1.5 hr | M32: =SUM(I32:K32) -> 2099 | N32: =Parameters!$B$7-G32 -> 2 | O32: =IF(N32<=7,"0-7 days",IF(N32<=14,"8-14 days",IF(N32<=30,"15-30 days","Over 30 days"))) -> 0-7 days | P32: Not received
A33: LFL-1047760 | B33: Copperline Freight Brokerage Inc. | C33: Gary, IN | D33: Columbus, OH | E33: Dry van 53 ft | F33: 46323 | G33: 46324 | H33: 331 | I33: 935 | J33: 152 | M33: =SUM(I33:K33) -> 1087 | N33: =Parameters!$B$7-G33 -> 2 | O33: =IF(N33<=7,"0-7 days",IF(N33<=14,"8-14 days",IF(N33<=30,"15-30 days","Over 30 days"))) -> 0-7 days | P33: Not received
A34: LFL-1047786 | B34: Copperline Freight Brokerage Inc. | C34: Joliet, IL | D34: Allentown, PA | E34: Dry van 53 ft | F34: 46323 | G34: 46325 | H34: 772 | I34: 1690 | J34: 355 | M34: =SUM(I34:K34) -> 2045 | N34: =Parameters!$B$7-G34 -> 1 | O34: =IF(N34<=7,"0-7 days",IF(N34<=14,"8-14 days",IF(N34<=30,"15-30 days","Over 30 days"))) -> 0-7 days | P34: Not received
A35: LFL-1047814 | B35: Copperline Freight Brokerage Inc. | C35: Joliet, IL | D35: Columbus, OH | E35: Dry van 53 ft | F35: 46324 | G35: 46325 | H35: 372 | I35: 1005 | J35: 171 | M35: =SUM(I35:K35) -> 1176 | N35: =Parameters!$B$7-G35 -> 1 | O35: =IF(N35<=7,"0-7 days",IF(N35<=14,"8-14 days",IF(N35<=30,"15-30 days","Over 30 days"))) -> 0-7 days | P35: Not received
A36: LFL-1046814 | B36: Kestrel Lane Logistics LLC | C36: Memphis, TN | D36: Laredo, TX | E36: Dry van 53 ft | F36: 46302 | G36: 46304 | H36: 878 | I36: 1930 | J36: 386 | K36: 75 | L36: Detention 1.5 hr | M36: =SUM(I36:K36) -> 2391 | N36: =Parameters!$B$7-G36 -> 22 | O36: =IF(N36<=7,"0-7 days",IF(N36<=14,"8-14 days",IF(N36<=30,"15-30 days","Over 30 days"))) -> 15-30 days | P36: Received, on hold | Q36: Broker billed 3 hr detention; 1.5 hr approved per check-in times. Accrued at the approved amount.
A37: LFL-1047087 | B37: Kestrel Lane Logistics LLC | C37: Memphis, TN | D37: Dallas, TX | E37: Dry van 53 ft | F37: 46308 | G37: 46309 | H37: 452 | I37: 1105 | J37: 199 | M37: =SUM(I37:K37) -> 1304 | N37: =Parameters!$B$7-G37 -> 17 | O37: =IF(N37<=7,"0-7 days",IF(N37<=14,"8-14 days",IF(N37<=30,"15-30 days","Over 30 days"))) -> 15-30 days | P37: Not received
A38: LFL-1047178 | B38: Kestrel Lane Logistics LLC | C38: Memphis, TN | D38: Houston, TX | E38: Dry van 53 ft | F38: 46310 | G38: 46311 | H38: 563 | I38: 1345 | J38: 248 | M38: =SUM(I38:K38) -> 1593 | N38: =Parameters!$B$7-G38 -> 15 | O38: =IF(N38<=7,"0-7 days",IF(N38<=14,"8-14 days",IF(N38<=30,"15-30 days","Over 30 days"))) -> 15-30 days | P38: Not received
A39: LFL-1047242 | B39: Kestrel Lane Logistics LLC | C39: Memphis, TN | D39: San Antonio, TX | E39: Dry van 53 ft | F39: 46312 | G39: 46314 | H39: 725 | I39: 1580 | J39: 319 | M39: =SUM(I39:K39) -> 1899 | N39: =Parameters!$B$7-G39 -> 12 | O39: =IF(N39<=7,"0-7 days",IF(N39<=14,"8-14 days",IF(N39<=30,"15-30 days","Over 30 days"))) -> 8-14 days | P39: Not received
A40: LFL-1047355 | B40: Kestrel Lane Logistics LLC | C40: Memphis, TN | D40: Oklahoma City, OK | E40: Dry van 53 ft | F40: 46314 | G40: 46315 | H40: 467 | I40: 1155 | J40: 205 | M40: =SUM(I40:K40) -> 1360 | N40: =Parameters!$B$7-G40 -> 11 | O40: =IF(N40<=7,"0-7 days",IF(N40<=14,"8-14 days",IF(N40<=30,"15-30 days","Over 30 days"))) -> 8-14 days | P40: Not received
...

Sheet By Broker
A1: Broker | B1: Billing | C1: Loads | D1: Linehaul | E1: Fuel surcharge | F1: Accessorials | G1: Total | H1: % of total | I1: Avg per load | J1: On hold
A2: Ironbridge Logistics Brokerage LLC | B2: Monthly statement | C2: =COUNTIF('Load Detail'!$B$2:$B$103,$A2) -> 13 | D2: =SUMIF('Load Detail'!$B$2:$B$103,$A2,'Load Detail'!$I$2:$I$103) -> 20275 | E2: =SUMIF('Load Detail'!$B$2:$B$103,$A2,'Load Detail'!$J$2:$J$103) -> 4212 | F2: =SUMIF('Load Detail'!$B$2:$B$103,$A2,'Load Detail'!$K$2:$K$103) -> 340 | G2: =SUM(D2:F2) -> 24827 | H2: =IF($G$9=0,0,G2/$G$9) -> 0.13317777 | I2: =IF(C2=0,0,G2/C2) -> 1909.7692 | J2: =COUNTIFS('Load Detail'!$B$2:$B$103,$A2,'Load Detail'!$P$2:$P$103,"Received, on hold") -> 0
A3: Copperline Freight Brokerage Inc. | B3: Per load | C3: =COUNTIF('Load Detail'!$B$2:$B$103,$A3) -> 21 | D3: =SUMIF('Load Detail'!$B$2:$B$103,$A3,'Load Detail'!$I$2:$I$103) -> 29810 | E3: =SUMIF('Load Detail'!$B$2:$B$103,$A3,'Load Detail'!$J$2:$J$103) -> 5613 | F3: =SUMIF('Load Detail'!$B$2:$B$103,$A3,'Load Detail'!$K$2:$K$103) -> 575 | G3: =SUM(D3:F3) -> 35998 | H3: =IF($G$9=0,0,G3/$G$9) -> 0.1931016 | I3: =IF(C3=0,0,G3/C3) -> 1714.1905 | J3: =COUNTIFS('Load Detail'!$B$2:$B$103,$A3,'Load Detail'!$P$2:$P$103,"Received, on hold") -> 1
A4: Kestrel Lane Logistics LLC | B4: Per load | C4: =COUNTIF('Load Detail'!$B$2:$B$103,$A4) -> 18 | D4: =SUMIF('Load Detail'!$B$2:$B$103,$A4,'Load Detail'!$I$2:$I$103) -> 28140 | E4: =SUMIF('Load Detail'!$B$2:$B$103,$A4,'Load Detail'!$J$2:$J$103) -> 5487 | F4: =SUMIF('Load Detail'!$B$2:$B$103,$A4,'Load Detail'!$K$2:$K$103) -> 250 | G4: =SUM(D4:F4) -> 33877 | H4: =IF($G$9=0,0,G4/$G$9) -> 0.18172406 | I4: =IF(C4=0,0,G4/C4) -> 1882.0556 | J4: =COUNTIFS('Load Detail'!$B$2:$B$103,$A4,'Load Detail'!$P$2:$P$103,"Received, on hold") -> 1
A5: Sable Creek Freight Partners LLC | B5: Per load | C5: =COUNTIF('Load Detail'!$B$2:$B$103,$A5) -> 15 | D5: =SUMIF('Load Detail'!$B$2:$B$103,$A5,'Load Detail'!$I$2:$I$103) -> 31555 | E5: =SUMIF('Load Detail'!$B$2:$B$103,$A5,'Load Detail'!$J$2:$J$103) -> 6241 | F5: =SUMIF('Load Detail'!$B$2:$B$103,$A5,'Load Detail'!$K$2:$K$103) -> 960 | G5: =SUM(D5:F5) -> 38756 | H5: =IF($G$9=0,0,G5/$G$9) -> 0.20789615 | I5: =IF(C5=0,0,G5/C5) -> 2583.7333 | J5: =COUNTIFS('Load Detail'!$B$2:$B$103,$A5,'Load Detail'!$P$2:$P$103,"Received, on hold") -> 1
A6: Larkfield Transport Brokerage LLC | B6: Per load | C6: =COUNTIF('Load Detail'!$B$2:$B$103,$A6) -> 14 | D6: =SUMIF('Load Detail'!$B$2:$B$103,$A6,'Load Detail'!$I$2:$I$103) -> 22850 | E6: =SUMIF('Load Detail'!$B$2:$B$103,$A6,'Load Detail'!$J$2:$J$103) -> 4440 | F6: =SUMIF('Load Detail'!$B$2:$B$103,$A6,'Load Detail'!$K$2:$K$103) -> 225 | G6: =SUM(D6:F6) -> 27515 | H6: =IF($G$9=0,0,G6/$G$9) -> 0.14759682 | I6: =IF(C6=0,0,G6/C6) -> 1965.3571 | J6: =COUNTIFS('Load Detail'!$B$2:$B$103,$A6,'Load Detail'!$P$2:$P$103,"Received, on hold") -> 1
A7: Millrace Logistics Group Inc. | B7: Per load | C7: =COUNTIF('Load Detail'!$B$2:$B$103,$A7) -> 12 | D7: =SUMIF('Load Detail'!$B$2:$B$103,$A7,'Load Detail'!$I$2:$I$103) -> 14815 | E7: =SUMIF('Load Detail'!$B$2:$B$103,$A7,'Load Detail'!$J$2:$J$103) -> 2560 | F7: =SUMIF('Load Detail'!$B$2:$B$103,$A7,'Load Detail'!$K$2:$K$103) -> 325 | G7: =SUM(D7:F7) -> 17700 | H7: =IF($G$9=0,0,G7/$G$9) -> 0.094946894 | I7: =IF(C7=0,0,G7/C7) -> 1475 | J7: =COUNTIFS('Load Detail'!$B$2:$B$103,$A7,'Load Detail'!$P$2:$P$103,"Received, on hold") -> 0
A8: Foxglove Freight Solutions LLC | B8: Per load | C8: =COUNTIF('Load Detail'!$B$2:$B$103,$A8) -> 9 | D8: =SUMIF('Load Detail'!$B$2:$B$103,$A8,'Load Detail'!$I$2:$I$103) -> 6745 | E8: =SUMIF('Load Detail'!$B$2:$B$103,$A8,'Load Detail'!$J$2:$J$103) -> 927 | F8: =SUMIF('Load Detail'!$B$2:$B$103,$A8,'Load Detail'!$K$2:$K$103) -> 75 | G8: =SUM(D8:F8) -> 7747 | H8: =IF($G$9=0,0,G8/$G$9) -> 0.0415567 | I8: =IF(C8=0,0,G8/C8) -> 860.77778 | J8: =COUNTIFS('Load Detail'!$B$2:$B$103,$A8,'Load Detail'!$P$2:$P$103,"Received, on hold") -> 0
A9: Total | C9: =SUM(C2:C8) -> 102 | D9: =SUM(D2:D8) -> 154190 | E9: =SUM(E2:E8) -> 29480 | F9: =SUM(F2:F8) -> 2750 | G9: =SUM(G2:G8) -> 186420 | H9: =SUM(H2:H8) -> 1 | I9: =IF(C9=0,0,G9/C9) -> 1827.6471 | J9: =SUM(J2:J8) -> 4
A11: Check: agrees to Load Detail | C11: =C9-'Load Detail'!B105 -> 0 | G11: =G9-'Load Detail'!M105 -> 0

Sheet Aging
A1: Aging bucket | B1: Days from | C1: Days to | D1: Loads | E1: Amount | F1: % of amount
A2: 0-7 days | B2: 0 | C2: 7 | D2: =COUNTIFS('Load Detail'!$N$2:$N$103,">="&B2,'Load Detail'!$N$2:$N$103,"<="&C2) -> 46 | E2: =SUMIFS('Load Detail'!$M$2:$M$103,'Load Detail'!$N$2:$N$103,">="&B2,'Load Detail'!$N$2:$N$103,"<="&C2) -> 81360 | F2: =IF($E$6=0,0,E2/$E$6) -> 0.43643386
A3: 8-14 days | B3: 8 | C3: 14 | D3: =COUNTIFS('Load Detail'!$N$2:$N$103,">="&B3,'Load Detail'!$N$2:$N$103,"<="&C3) -> 37 | E3: =SUMIFS('Load Detail'!$M$2:$M$103,'Load Detail'!$N$2:$N$103,">="&B3,'Load Detail'!$N$2:$N$103,"<="&C3) -> 67029 | F3: =IF($E$6=0,0,E3/$E$6) -> 0.35955906
A4: 15-30 days | B4: 15 | C4: 30 | D4: =COUNTIFS('Load Detail'!$N$2:$N$103,">="&B4,'Load Detail'!$N$2:$N$103,"<="&C4) -> 18 | E4: =SUMIFS('Load Detail'!$M$2:$M$103,'Load Detail'!$N$2:$N$103,">="&B4,'Load Detail'!$N$2:$N$103,"<="&C4) -> 36119 | F4: =IF($E$6=0,0,E4/$E$6) -> 0.19375067
A5: Over 30 days | B5: 31 | D5: =COUNTIFS('Load Detail'!$N$2:$N$103,">="&B5) -> 1 | E5: =SUMIFS('Load Detail'!$M$2:$M$103,'Load Detail'!$N$2:$N$103,">="&B5) -> 1912 | F5: =IF($E$6=0,0,E5/$E$6) -> 0.01025641
A6: Total | D6: =SUM(D2:D5) -> 102 | E6: =SUM(E2:E5) -> 186420 | F6: =SUM(F2:F5) -> 1
A8: Broker | B8: 0-7 days | C8: 8-14 days | D8: 15-30 days | E8: Over 30 days | F8: Total
A9: ='By Broker'!A2 -> Ironbridge Logistics Brokerage LLC | B9: =SUMIFS('Load Detail'!$M$2:$M$103,'Load Detail'!$B$2:$B$103,$A9,'Load Detail'!$O$2:$O$103,B$8) -> 5368 | C9: =SUMIFS('Load Detail'!$M$2:$M$103,'Load Detail'!$B$2:$B$103,$A9,'Load Detail'!$O$2:$O$103,C$8) -> 6007 | D9: =SUMIFS('Load Detail'!$M$2:$M$103,'Load Detail'!$B$2:$B$103,$A9,'Load Detail'!$O$2:$O$103,D$8) -> 13452 | E9: =SUMIFS('Load Detail'!$M$2:$M$103,'Load Detail'!$B$2:$B$103,$A9,'Load Detail'!$O$2:$O$103,E$8) -> 0 | F9: =SUM(B9:E9) -> 24827
A10: ='By Broker'!A3 -> Copperline Freight Brokerage Inc. | B10: =SUMIFS('Load Detail'!$M$2:$M$103,'Load Detail'!$B$2:$B$103,$A10,'Load Detail'!$O$2:$O$103,B$8) -> 17858 | C10: =SUMIFS('Load Detail'!$M$2:$M$103,'Load Detail'!$B$2:$B$103,$A10,'Load Detail'!$O$2:$O$103,C$8) -> 12562 | D10: =SUMIFS('Load Detail'!$M$2:$M$103,'Load Detail'!$B$2:$B$103,$A10,'Load Detail'!$O$2:$O$103,D$8) -> 3666 | E10: =SUMIFS('Load Detail'!$M$2:$M$103,'Load Detail'!$B$2:$B$103,$A10,'Load Detail'!$O$2:$O$103,E$8) -> 1912 | F10: =SUM(B10:E10) -> 35998
A11: ='By Broker'!A4 -> Kestrel Lane Logistics LLC | B11: =SUMIFS('Load Detail'!$M$2:$M$103,'Load Detail'!$B$2:$B$103,$A11,'Load Detail'!$O$2:$O$103,B$8) -> 14327 | C11: =SUMIFS('Load Detail'!$M$2:$M$103,'Load Detail'!$B$2:$B$103,$A11,'Load Detail'!$O$2:$O$103,C$8) -> 14262 | D11: =SUMIFS('Load Detail'!$M$2:$M$103,'Load Detail'!$B$2:$B$103,$A11,'Load Detail'!$O$2:$O$103,D$8) -> 5288 | E11: =SUMIFS('Load Detail'!$M$2:$M$103,'Load Detail'!$B$2:$B$103,$A11,'Load Detail'!$O$2:$O$103,E$8) -> 0 | F11: =SUM(B11:E11) -> 33877
A12: ='By Broker'!A5 -> Sable Creek Freight Partners LLC | B12: =SUMIFS('Load Detail'!$M$2:$M$103,'Load Detail'!$B$2:$B$103,$A12,'Load Detail'!$O$2:$O$103,B$8) -> 18180 | C12: =SUMIFS('Load Detail'!$M$2:$M$103,'Load Detail'!$B$2:$B$103,$A12,'Load Detail'!$O$2:$O$103,C$8) -> 12893 | D12: =SUMIFS('Load Detail'!$M$2:$M$103,'Load Detail'!$B$2:$B$103,$A12,'Load Detail'!$O$2:$O$103,D$8) -> 7683 | E12: =SUMIFS('Load Detail'!$M$2:$M$103,'Load Detail'!$B$2:$B$103,$A12,'Load Detail'!$O$2:$O$103,E$8) -> 0 | F12: =SUM(B12:E12) -> 38756
A13: ='By Broker'!A6 -> Larkfield Transport Brokerage LLC | B13: =SUMIFS('Load Detail'!$M$2:$M$103,'Load Detail'!$B$2:$B$103,$A13,'Load Detail'!$O$2:$O$103,B$8) -> 11652 | C13: =SUMIFS('Load Detail'!$M$2:$M$103,'Load Detail'!$B$2:$B$103,$A13,'Load Detail'!$O$2:$O$103,C$8) -> 11887 | D13: =SUMIFS('Load Detail'!$M$2:$M$103,'Load Detail'!$B$2:$B$103,$A13,'Load Detail'!$O$2:$O$103,D$8) -> 3976 | E13: =SUMIFS('Load Detail'!$M$2:$M$103,'Load Detail'!$B$2:$B$103,$A13,'Load Detail'!$O$2:$O$103,E$8) -> 0 | F13: =SUM(B13:E13) -> 27515
A14: ='By Broker'!A7 -> Millrace Logistics Group Inc. | B14: =SUMIFS('Load Detail'!$M$2:$M$103,'Load Detail'!$B$2:$B$103,$A14,'Load Detail'!$O$2:$O$103,B$8) -> 8735 | C14: =SUMIFS('Load Detail'!$M$2:$M$103,'Load Detail'!$B$2:$B$103,$A14,'Load Detail'!$O$2:$O$103,C$8) -> 6911 | D14: =SUMIFS('Load Detail'!$M$2:$M$103,'Load Detail'!$B$2:$B$103,$A14,'Load Detail'!$O$2:$O$103,D$8) -> 2054 | E14: =SUMIFS('Load Detail'!$M$2:$M$103,'Load Detail'!$B$2:$B$103,$A14,'Load Detail'!$O$2:$O$103,E$8) -> 0 | F14: =SUM(B14:E14) -> 17700
A15: ='By Broker'!A8 -> Foxglove Freight Solutions LLC | B15: =SUMIFS('Load Detail'!$M$2:$M$103,'Load Detail'!$B$2:$B$103,$A15,'Load Detail'!$O$2:$O$103,B$8) -> 5240 | C15: =SUMIFS('Load Detail'!$M$2:$M$103,'Load Detail'!$B$2:$B$103,$A15,'Load Detail'!$O$2:$O$103,C$8) -> 2507 | D15: =SUMIFS('Load Detail'!$M$2:$M$103,'Load Detail'!$B$2:$B$103,$A15,'Load Detail'!$O$2:$O$103,D$8) -> 0 | E15: =SUMIFS('Load Detail'!$M$2:$M$103,'Load Detail'!$B$2:$B$103,$A15,'Load Detail'!$O$2:$O$103,E$8) -> 0 | F15: =SUM(B15:E15) -> 7747
A16: Total | B16: =SUM(B9:B15) -> 81360 | C16: =SUM(C9:C15) -> 67029 | D16: =SUM(D9:D15) -> 36119 | E16: =SUM(E9:E15) -> 1912 | F16: =SUM(F9:F15) -> 186420
A18: Check: agrees to bucket table | F18: =F16-E6 -> 0

Sheet Parameters
A1: Parameter | B1: Value
A2: Report | B2: Unbilled Broker Loads
A3: Company | B3: Lakeshore Freight Logistics
A4: Source | B4: TMS freight pay, carrier cost accrual
A5: Accrual period | B5: OCT-26
A6: Period start | B6: 46296
A7: As-of date (period end) | B7: 46326
A8: Generated | B8: 46325.578
A9: Time zone | B9: America/Chicago (CT)
A10: Generated by | B10: mkeane
A11: Carrier type | B11: Freight broker (third party)
A12: Mode | B12: Truckload: dry van, reefer, power only
A13: Load status | B13: Delivered, delivery date on or before the as-of date
A14: Freight bill status | B14: No approved broker invoice: not received, monthly statement pending, or received and on hold
A15: Excluded | B15: Company-driver loads, loads with an approved broker invoice, cancelled loads
A16: Amount basis | B16: Rate confirmation: linehaul, fuel surcharge and approved accessorials
A17: Currency | B17: USD
A18: GL debit | B18: 5120-000 Purchased Transportation, Brokers
A19: GL credit | B19: 2150-000 Accrued Freight
A20: Reversal | B20: Auto-reverses on day 1 of the next period (NOV-26)
... A35: Freight pay note | B35: Audit note on a held broker invoice
